<sdf version='1.9'>
  <model name='diff_bot'>
    <link name='base_link'>
      <inertial>
        <pose>0 0 0 0 0 0</pose>
        <mass>0.010288200184753521</mass>
        <inertia>
          <ixx>9.2e-05</ixx>
          <ixy>0</ixy>
          <ixz>0</ixz>
          <iyy>4.8999999999999998e-05</iyy>
          <iyz>0</iyz>
          <izz>0.000111</izz>
        </inertia>
      </inertial>
      <visual name='base_link_visual'>
        <pose>0 0 0 0 0 0</pose>
        <geometry>
          <mesh>
            <scale>1 1 1</scale>
            <uri>model://model_pkg/models/base.dae</uri>
          </mesh>
        </geometry>
      </visual>
    </link>
    <joint name='left_wheel_joint' type='revolute'>
      <pose relative_to='base_link'>0.1 0.075 0.065 0 0 0</pose>
      <parent>base_link</parent>
      <child>left_wheel_link</child>
      <axis>
        <xyz>1 0 0</xyz>
        <limit>
          <lower>-10000000000000000</lower>
          <upper>10000000000000000</upper>
        </limit>
        <dynamics>
          <spring_reference>0</spring_reference>
          <spring_stiffness>0</spring_stiffness>
        </dynamics>
      </axis>
    </joint>
    <link name='left_wheel_link'>
      <pose relative_to='left_wheel_joint'>0 0 0 0 0 0</pose>
      <inertial>
        <pose>0 0 0 0 0 0</pose>
        <mass>0.00046597988319067868</mass>
        <inertia>
          <ixx>9.9999999999999995e-07</ixx>
          <ixy>0</ixy>
          <ixz>0</ixz>
          <iyy>9.9999999999999995e-07</iyy>
          <iyz>0</iyz>
          <izz>9.9999999999999995e-07</izz>
        </inertia>
      </inertial>
      <visual name='left_wheel_link_visual'>
        <pose>0 0 0 0 0 0</pose>
        <geometry>
          <mesh>
            <scale>1 1 1</scale>
            <uri>model://model_pkg/models/left_wheel.dae</uri>
          </mesh>
        </geometry>
      </visual>
    </link>
    <joint name='right_wheel_joint' type='revolute'>
      <pose relative_to='base_link'>-0.1 0.075 0.065 0 0 0</pose>
      <parent>base_link</parent>
      <child>right_wheel_link</child>
      <axis>
        <xyz>1 0 0</xyz>
        <limit>
          <lower>-10000000000000000</lower>
          <upper>10000000000000000</upper>
        </limit>
        <dynamics>
          <spring_reference>0</spring_reference>
          <spring_stiffness>0</spring_stiffness>
        </dynamics>
      </axis>
    </joint>
    <link name='right_wheel_link'>
      <pose relative_to='right_wheel_joint'>0 0 0 0 0 0</pose>
      <inertial>
        <pose>0 0 0 0 0 0</pose>
        <mass>0.000465979901520834</mass>
        <inertia>
          <ixx>9.9999999999999995e-07</ixx>
          <ixy>0</ixy>
          <ixz>0</ixz>
          <iyy>9.9999999999999995e-07</iyy>
          <iyz>0</iyz>
          <izz>9.9999999999999995e-07</izz>
        </inertia>
      </inertial>
      <visual name='right_wheel_link_visual'>
        <pose>0 0 0 0 0 0</pose>
        <geometry>
          <mesh>
            <scale>1 1 1</scale>
            <uri>model://model_pkg/models/right_wheel.dae</uri>
          </mesh>
        </geometry>
      </visual>
    </link>
  </model>
</sdf>
