<robot name="diff_bot">
    <link name="base_link">
        <inertial>
            <mass value="0.010288200184753522"/>
            <inertia ixx="0.000092" ixy="-0.000000" ixz="-0.000000" iyy="0.000049" iyz="-0.000000" izz="0.000111"/>
        </inertial>
        <visual>
            <geometry>
                <mesh filename="package://model_pkg/models/base.obj"/>
            </geometry>
        </visual>
    </link>

    <joint name="left_wheel_joint" type="continuous">
        <origin xyz="0.1 0.075 0.065"/>
        <parent link="base_link"/>
        <child link="left_wheel_link"/>
        <axis xyz="0 0 -1"/>
    </joint>

    <link name="left_wheel_link">
        <inertial>
            <mass value="0.00046597988319067873"/>
            <inertia ixx="0.000001" ixy="0.000000" ixz="0.000000" iyy="0.000001" iyz="0.000000" izz="0.000001"/>
        </inertial>
        <visual>
            <geometry>
                <mesh filename="package://model_pkg/models/left_wheel.obj"/>
            </geometry>
        </visual>
    </link>

    <joint name="right_wheel_joint" type="continuous">
        <origin xyz="-0.1 0.075 0.065"/>
        <parent link="base_link"/>
        <child link="right_wheel_link"/>
        <axis xyz="0 0 1"/>
    </joint>

    <link name="right_wheel_link">
        <inertial>
            <mass value="0.000465979901520834"/>
            <inertia ixx="0.000001" ixy="0.000000" ixz="-0.000000" iyy="0.000001" iyz="0.000000" izz="0.000001"/>
        </inertial>
        <visual>
            <geometry>
                <mesh filename="package://model_pkg/models/right_wheel.obj"/>
            </geometry>
        </visual>
    </link>

</robot>
